Modules Release 4.8.0 (2021-07-14)
DCC-SW: Added modules (2023-aug/XeonE5-2660v3)
DCC-SW: Removed standard modules: /apps/dcc/etc/ModulesSL73/modulefiles
DCC-SW: Using gnu/12.3.0 compiler (requested)
DCC-SW: Released modules (2023-aug/XeonE5-2660v3)
DCC-SW: Added modules (2020-aug/XeonE5-2660v3)
DCC-SW: Removed standard modules: /apps/dcc/etc/ModulesSL73/modulefiles
DCC-SW: Using gnu/9.3.0 compiler
Loading python/3.8.5
  Loading requirement: build-tools/1.0 gcc/9.3.0 zlib/1.2.11 expat/2.2.0
    libffi/3.3
Loading scalapack/2.1.0
  Loading requirement: numactl/2.0.12 libxml2/2.9.10 hwloc/2.2.0 knem/1.1.4
    ucx/1.8.1 openmpi/4.0.4
rank=11 L0: Traceback (most recent call last):
rank=11 L1:   File "soc.py", line 67, in <module>
rank=11 L2:     print(theta_tp.shape(), phi_tp.shape())
rank=11 L3: TypeError: 'tuple' object is not callable
GPAW CLEANUP (node 11): <class 'TypeError'> occurred.  Calling MPI_Abort!
rank=10 L0: Traceback (most recent call last):
rank=10 L1:   File "soc.py", line 67, in <module>
rank=10 L2:     print(theta_tp.shape(), phi_tp.shape())
rank=10 L3: TypeError: 'tuple' object is not callable
GPAW CLEANUP (node 10): <class 'TypeError'> occurred.  Calling MPI_Abort!
rank=07 L0: Traceback (most recent call last):
rank=07 L1:   File "soc.py", line 67, in <module>
rank=07 L2:     print(theta_tp.shape(), phi_tp.shape())
rank=07 L3: TypeError: 'tuple' object is not callable
GPAW CLEANUP (node 7): <class 'TypeError'> occurred.  Calling MPI_Abort!
rank=04 L0: Traceback (most recent call last):
rank=04 L1:   File "soc.py", line 67, in <module>
rank=04 L2:     print(theta_tp.shape(), phi_tp.shape())
rank=04 L3: TypeError: 'tuple' object is not callable
GPAW CLEANUP (node 4): <class 'TypeError'> occurred.  Calling MPI_Abort!
rank=03 L0: Traceback (most recent call last):
rank=03 L1:   File "soc.py", line 67, in <module>
rank=03 L2:     print(theta_tp.shape(), phi_tp.shape())
rank=03 L3: TypeError: 'tuple' object is not callable
GPAW CLEANUP (node 3): <class 'TypeError'> occurred.  Calling MPI_Abort!
rank=00 L0: Traceback (most recent call last):
rank=00 L1:   File "soc.py", line 67, in <module>
rank=00 L2:     print(theta_tp.shape(), phi_tp.shape())
rank=00 L3: TypeError: 'tuple' object is not callable
GPAW CLEANUP (node 0): <class 'TypeError'> occurred.  Calling MPI_Abort!
rank=08 L0: Traceback (most recent call last):
rank=08 L1:   File "soc.py", line 67, in <module>
rank=08 L2:     print(theta_tp.shape(), phi_tp.shape())
rank=08 L3: TypeError: 'tuple' object is not callable
GPAW CLEANUP (node 8): <class 'TypeError'> occurred.  Calling MPI_Abort!
rank=02 L0: Traceback (most recent call last):
rank=02 L1:   File "soc.py", line 67, in <module>
rank=02 L2:     print(theta_tp.shape(), phi_tp.shape())
rank=02 L3: TypeError: 'tuple' object is not callable
GPAW CLEANUP (node 2): <class 'TypeError'> occurred.  Calling MPI_Abort!
rank=01 L0: Traceback (most recent call last):
rank=01 L1:   File "soc.py", line 67, in <module>
rank=01 L2:     print(theta_tp.shape(), phi_tp.shape())
rank=01 L3: TypeError: 'tuple' object is not callable
GPAW CLEANUP (node 1): <class 'TypeError'> occurred.  Calling MPI_Abort!
rank=05 L0: Traceback (most recent call last):
rank=05 L1:   File "soc.py", line 67, in <module>
rank=05 L2:     print(theta_tp.shape(), phi_tp.shape())
rank=05 L3: TypeError: 'tuple' object is not callable
GPAW CLEANUP (node 5): <class 'TypeError'> occurred.  Calling MPI_Abort!
rank=09 L0: Traceback (most recent call last):
rank=09 L1:   File "soc.py", line 67, in <module>
rank=09 L2:     print(theta_tp.shape(), phi_tp.shape())
rank=09 L3: TypeError: 'tuple' object is not callable
GPAW CLEANUP (node 9): <class 'TypeError'> occurred.  Calling MPI_Abort!
rank=06 L0: Traceback (most recent call last):
rank=06 L1:   File "soc.py", line 67, in <module>
rank=06 L2:     print(theta_tp.shape(), phi_tp.shape())
rank=06 L3: TypeError: 'tuple' object is not callable
GPAW CLEANUP (node 6): <class 'TypeError'> occurred.  Calling MPI_Abort!
--------------------------------------------------------------------------
MPI_ABORT was invoked on rank 11 in communicator MPI_COMM_WORLD
with errorcode 42.

NOTE: invoking MPI_ABORT causes Open MPI to kill all MPI processes.
You may or may not see output from other processes, depending on
exactly when Open MPI kills them.
--------------------------------------------------------------------------
[n-62-29-24:19674] PMIX ERROR: UNREACHABLE in file ../../../../../../../opal/mca/pmix/pmix3x/pmix/src/server/pmix_server.c at line 2193
[n-62-29-24:19674] PMIX ERROR: UNREACHABLE in file ../../../../../../../opal/mca/pmix/pmix3x/pmix/src/server/pmix_server.c at line 2193
[n-62-29-24:19674] PMIX ERROR: UNREACHABLE in file ../../../../../../../opal/mca/pmix/pmix3x/pmix/src/server/pmix_server.c at line 2193
[n-62-29-24:19674] PMIX ERROR: UNREACHABLE in file ../../../../../../../opal/mca/pmix/pmix3x/pmix/src/server/pmix_server.c at line 2193
[n-62-29-24:19674] PMIX ERROR: UNREACHABLE in file ../../../../../../../opal/mca/pmix/pmix3x/pmix/src/server/pmix_server.c at line 2193
[n-62-29-24:19674] PMIX ERROR: UNREACHABLE in file ../../../../../../../opal/mca/pmix/pmix3x/pmix/src/server/pmix_server.c at line 2193
[n-62-29-24:19674] PMIX ERROR: UNREACHABLE in file ../../../../../../../opal/mca/pmix/pmix3x/pmix/src/server/pmix_server.c at line 2193
[n-62-29-24:19674] PMIX ERROR: UNREACHABLE in file ../../../../../../../opal/mca/pmix/pmix3x/pmix/src/server/pmix_server.c at line 2193
[n-62-29-24:19674] PMIX ERROR: UNREACHABLE in file ../../../../../../../opal/mca/pmix/pmix3x/pmix/src/server/pmix_server.c at line 2193
[n-62-29-24:19674] PMIX ERROR: UNREACHABLE in file ../../../../../../../opal/mca/pmix/pmix3x/pmix/src/server/pmix_server.c at line 2193
[n-62-29-24:19674] PMIX ERROR: UNREACHABLE in file ../../../../../../../opal/mca/pmix/pmix3x/pmix/src/server/pmix_server.c at line 2193
[n-62-29-24:19674] 11 more processes have sent help message help-mpi-api.txt / mpi-abort
[n-62-29-24:19674] Set MCA parameter "orte_base_help_aggregate" to 0 to see all help / error messages
