Modules Release 4.8.0 (2021-07-14)
DCC-SW: Added modules (2023-aug/XeonE5-2660v3)
DCC-SW: Removed standard modules: /apps/dcc/etc/ModulesSL73/modulefiles
DCC-SW: Using gnu/12.3.0 compiler (requested)
DCC-SW: Released modules (2023-aug/XeonE5-2660v3)
DCC-SW: Added modules (2020-aug/XeonE5-2660v3)
DCC-SW: Removed standard modules: /apps/dcc/etc/ModulesSL73/modulefiles
DCC-SW: Using gnu/9.3.0 compiler
Loading python/3.8.5
  Loading requirement: build-tools/1.0 gcc/9.3.0 zlib/1.2.11 expat/2.2.0
    libffi/3.3
Loading scalapack/2.1.0
  Loading requirement: numactl/2.0.12 libxml2/2.9.10 hwloc/2.2.0 knem/1.1.4
    ucx/1.8.1 openmpi/4.0.4
rank=4 L0: Traceback (most recent call last):
rank=4 L1:   File "soc.py", line 49, in <module>
rank=4 L2:     energies = np.load('data_600.0_6.0_6.0.npz')['energies']
rank=4 L3:   File "/zhome/87/8/147075/venv-name/lib/python3.8/site-packages/numpy/lib/npyio.py", line 405, in load
rank=4 L4:     fid = stack.enter_context(open(os_fspath(file), "rb"))
rank=4 L5: FileNotFoundError: [Errno 2] No such file or directory: 'data_600.0_6.0_6.0.npz'
GPAW CLEANUP (node 4): <class 'FileNotFoundError'> occurred.  Calling MPI_Abort!
rank=5 L0: Traceback (most recent call last):
rank=5 L1:   File "soc.py", line 49, in <module>
rank=5 L2:     energies = np.load('data_600.0_6.0_6.0.npz')['energies']
rank=5 L3:   File "/zhome/87/8/147075/venv-name/lib/python3.8/site-packages/numpy/lib/npyio.py", line 405, in load
rank=5 L4:     fid = stack.enter_context(open(os_fspath(file), "rb"))
rank=5 L5: FileNotFoundError: [Errno 2] No such file or directory: 'data_600.0_6.0_6.0.npz'
rank=3 L0: Traceback (most recent call last):
rank=3 L1:   File "soc.py", line 49, in <module>
rank=3 L2:     energies = np.load('data_600.0_6.0_6.0.npz')['energies']
rank=3 L3:   File "/zhome/87/8/147075/venv-name/lib/python3.8/site-packages/numpy/lib/npyio.py", line 405, in load
rank=3 L4:     fid = stack.enter_context(open(os_fspath(file), "rb"))
rank=3 L5: FileNotFoundError: [Errno 2] No such file or directory: 'data_600.0_6.0_6.0.npz'
rank=0 L0: Traceback (most recent call last):
rank=0 L1:   File "soc.py", line 49, in <module>
rank=0 L2:     energies = np.load('data_600.0_6.0_6.0.npz')['energies']
rank=0 L3:   File "/zhome/87/8/147075/venv-name/lib/python3.8/site-packages/numpy/lib/npyio.py", line 405, in load
rank=0 L4:     fid = stack.enter_context(open(os_fspath(file), "rb"))
rank=0 L5: FileNotFoundError: [Errno 2] No such file or directory: 'data_600.0_6.0_6.0.npz'
GPAW CLEANUP (node 0): <class 'FileNotFoundError'> occurred.  Calling MPI_Abort!
rank=1 L0: Traceback (most recent call last):
rank=1 L1:   File "soc.py", line 49, in <module>
rank=1 L2:     energies = np.load('data_600.0_6.0_6.0.npz')['energies']
rank=1 L3:   File "/zhome/87/8/147075/venv-name/lib/python3.8/site-packages/numpy/lib/npyio.py", line 405, in load
rank=1 L4:     fid = stack.enter_context(open(os_fspath(file), "rb"))
rank=1 L5: FileNotFoundError: [Errno 2] No such file or directory: 'data_600.0_6.0_6.0.npz'
GPAW CLEANUP (node 1): <class 'FileNotFoundError'> occurred.  Calling MPI_Abort!
rank=2 L0: Traceback (most recent call last):
rank=2 L1:   File "soc.py", line 49, in <module>
rank=2 L2:     energies = np.load('data_600.0_6.0_6.0.npz')['energies']
rank=2 L3:   File "/zhome/87/8/147075/venv-name/lib/python3.8/site-packages/numpy/lib/npyio.py", line 405, in load
rank=2 L4:     fid = stack.enter_context(open(os_fspath(file), "rb"))
rank=2 L5: FileNotFoundError: [Errno 2] No such file or directory: 'data_600.0_6.0_6.0.npz'
GPAW CLEANUP (node 2): <class 'FileNotFoundError'> occurred.  Calling MPI_Abort!
GPAW CLEANUP (node 5): <class 'FileNotFoundError'> occurred.  Calling MPI_Abort!
rank=6 L0: Traceback (most recent call last):
rank=6 L1:   File "soc.py", line 49, in <module>
rank=6 L2:     energies = np.load('data_600.0_6.0_6.0.npz')['energies']
rank=6 L3:   File "/zhome/87/8/147075/venv-name/lib/python3.8/site-packages/numpy/lib/npyio.py", line 405, in load
rank=6 L4:     fid = stack.enter_context(open(os_fspath(file), "rb"))
rank=6 L5: FileNotFoundError: [Errno 2] No such file or directory: 'data_600.0_6.0_6.0.npz'
GPAW CLEANUP (node 6): <class 'FileNotFoundError'> occurred.  Calling MPI_Abort!
rank=7 L0: Traceback (most recent call last):
rank=7 L1:   File "soc.py", line 49, in <module>
rank=7 L2:     energies = np.load('data_600.0_6.0_6.0.npz')['energies']
rank=7 L3:   File "/zhome/87/8/147075/venv-name/lib/python3.8/site-packages/numpy/lib/npyio.py", line 405, in load
rank=7 L4:     fid = stack.enter_context(open(os_fspath(file), "rb"))
rank=7 L5: FileNotFoundError: [Errno 2] No such file or directory: 'data_600.0_6.0_6.0.npz'
GPAW CLEANUP (node 7): <class 'FileNotFoundError'> occurred.  Calling MPI_Abort!
rank=8 L0: Traceback (most recent call last):
rank=8 L1:   File "soc.py", line 49, in <module>
rank=8 L2:     energies = np.load('data_600.0_6.0_6.0.npz')['energies']
rank=8 L3:   File "/zhome/87/8/147075/venv-name/lib/python3.8/site-packages/numpy/lib/npyio.py", line 405, in load
rank=8 L4:     fid = stack.enter_context(open(os_fspath(file), "rb"))
rank=8 L5: FileNotFoundError: [Errno 2] No such file or directory: 'data_600.0_6.0_6.0.npz'
GPAW CLEANUP (node 8): <class 'FileNotFoundError'> occurred.  Calling MPI_Abort!
rank=9 L0: Traceback (most recent call last):
rank=9 L1:   File "soc.py", line 49, in <module>
rank=9 L2:     energies = np.load('data_600.0_6.0_6.0.npz')['energies']
rank=9 L3:   File "/zhome/87/8/147075/venv-name/lib/python3.8/site-packages/numpy/lib/npyio.py", line 405, in load
rank=9 L4:     fid = stack.enter_context(open(os_fspath(file), "rb"))
rank=9 L5: FileNotFoundError: [Errno 2] No such file or directory: 'data_600.0_6.0_6.0.npz'
GPAW CLEANUP (node 9): <class 'FileNotFoundError'> occurred.  Calling MPI_Abort!
GPAW CLEANUP (node 3): <class 'FileNotFoundError'> occurred.  Calling MPI_Abort!
--------------------------------------------------------------------------
MPI_ABORT was invoked on rank 7 in communicator MPI_COMM_WORLD
with errorcode 42.

NOTE: invoking MPI_ABORT causes Open MPI to kill all MPI processes.
You may or may not see output from other processes, depending on
exactly when Open MPI kills them.
--------------------------------------------------------------------------
[n-62-29-22:16543] PMIX ERROR: UNREACHABLE in file ../../../../../../../opal/mca/pmix/pmix3x/pmix/src/server/pmix_server.c at line 2193
[n-62-29-22:16543] 9 more processes have sent help message help-mpi-api.txt / mpi-abort
[n-62-29-22:16543] Set MCA parameter "orte_base_help_aggregate" to 0 to see all help / error messages
